<?xml version="1.0" ?>
<!-- =================================================================================== -->
<!-- |    This document was autogenerated by xacro from crane_model_v02.urdf.xacro     | -->
<!-- |    EDITING THIS FILE BY HAND IS NOT RECOMMENDED                                 | -->
<!-- =================================================================================== -->
<robot name="crane_model_v02">
  <!-- <xacro:macro name="param_gamma_1" params="theta_1_d export_name:='gamma_1'">
    <xacro:property name="${export_name}" value="${pi/2-theta_1_d -atan(l_b1x/(l_0-l_b1z))-atan(l_b4y/l_b4x)}"/>
  </xacro:macro>
  <xacro:macro name="param_gamma_2" params="theta_2_d export_name:='gamma_2'">
    <xacro:property name="${export_name}" value="${pi-theta_2_d -atan(l_c1y/l_c1x)-atan(l_c3y/l_c3x)}"/>
  </xacro:macro> -->
  <!-- Note: do $(find package_name) when compiled -->
  <link name="base_link">
    <visual>
      <geometry>
        <cylinder length="0.2" radius="0.3"/>
      </geometry>
      <origin rpy="0 0 0" xyz="0 0 0.1"/>
    </visual>
    <collision>
      <geometry>
        <cylinder length="0.15000000000000002" radius="0.3"/>
      </geometry>
      <origin rpy="0 0 0" xyz="0 0 0.1"/>
    </collision>
    <!-- <xacro:generate_cylinder_inertial mass="500" r="${r_base}" l="${l_base}" /> -->
  </link>
  <link name="arm_1">
    <visual>
      <geometry>
        <box size="0.3 0.3 2.1"/>
      </geometry>
      <origin rpy="0 0 0" xyz="0 0 1.25"/>
    </visual>
    <collision>
      <geometry>
        <box size="0.24 0.24 1.75"/>
      </geometry>
      <origin rpy="0 0 0" xyz="0 0 1.25"/>
    </collision>
    <inertial>
      <mass value="800"/>
      <inertia ixx="299.99999999999994" ixy="0.0" ixz="0.0" iyy="299.99999999999994" iyz="0.0" izz="11.999999999999998"/>
    </inertial>
  </link>
  <link name="arm_2">
    <visual>
      <geometry>
        <box size="0.3 0.3 2.3"/>
      </geometry>
      <origin rpy="1.5707963267948966 0 0" xyz="0 1.15 0"/>
    </visual>
    <collision>
      <geometry>
        <box size="0.24 0.24 1.9499999999999997"/>
      </geometry>
      <origin rpy="1.5707963267948966 0 0" xyz="0 1.15 0"/>
    </collision>
    <inertial>
      <mass value="750"/>
      <inertia ixx="336.24999999999994" ixy="0.0" ixz="0.0" iyy="336.24999999999994" iyz="0.0" izz="11.25"/>
    </inertial>
  </link>
  <link name="arm_3">
    <visual>
      <geometry>
        <box size="0.3 0.3 2.1"/>
      </geometry>
      <origin rpy="1.5707963267948966 0 0" xyz="0 1.05 0"/>
    </visual>
    <collision>
      <geometry>
        <box size="0.24 0.24 1.75"/>
      </geometry>
      <origin rpy="1.5707963267948966 0 0" xyz="0 1.05 0"/>
    </collision>
    <inertial>
      <mass value="700"/>
      <inertia ixx="313.83333333333326" ixy="0.0" ixz="0.0" iyy="313.83333333333326" iyz="0.0" izz="10.499999999999998"/>
    </inertial>
  </link>
  <link name="end_effector_temp">
    <visual>
      <geometry>
        <box size="0.1 0.1 0.1"/>
      </geometry>
      <origin rpy="1.5707963267948966 0 0" xyz="0 0 0"/>
    </visual>
    <inertial>
      <mass value="10"/>
      <inertia ixx="0.01666666666666667" ixy="0.0" ixz="0.0" iyy="0.01666666666666667" iyz="0.0" izz="0.01666666666666667"/>
    </inertial>
  </link>
  <link name="act_1_cyl">
    <!-- Rot angle (x) = atan2(l_0-l_b1x, a_1-l_b1x)  -->
    <visual>
      <geometry>
        <cylinder length="1.0" radius="0.125"/>
      </geometry>
      <origin rpy="0 0 0" xyz="0 0 0.5"/>
    </visual>
    <collision>
      <geometry>
        <cylinder length="0.8" radius="0.1"/>
      </geometry>
      <origin rpy="0 0 0" xyz="0 0 0.5"/>
    </collision>
    <inertial>
      <mass value="125"/>
      <inertia ixx="10.904947916666666" ixy="0.0" ixz="0.0" iyy="10.904947916666666" iyz="0.0" izz="0.16276041666666666"/>
    </inertial>
  </link>
  <link name="act_1_rod">
    <visual>
      <geometry>
        <cylinder length="0.9" radius="0.1"/>
      </geometry>
      <origin rpy="0 0 0" xyz="0 0 0.45"/>
    </visual>
    <collision>
      <geometry>
        <cylinder length="0.7200000000000001" radius="0.1"/>
      </geometry>
      <origin rpy="0 0 0" xyz="0 0 0.45"/>
    </collision>
    <inertial>
      <mass value="100"/>
      <inertia ixx="7.140624999999999" ixy="0.0" ixz="0.0" iyy="7.140624999999999" iyz="0.0" izz="0.13020833333333331"/>
    </inertial>
  </link>
  <link name="act_2_cyl">
    <visual>
      <geometry>
        <cylinder length="0.6" radius="0.125"/>
      </geometry>
      <origin rpy="0 0 0" xyz="0 0 0.3"/>
    </visual>
    <collision>
      <geometry>
        <cylinder length="0.48" radius="0.1"/>
      </geometry>
      <origin rpy="0 0 0" xyz="0 0 0.3"/>
    </collision>
    <inertial>
      <mass value="125"/>
      <inertia ixx="4.23828125" ixy="0.0" ixz="0.0" iyy="4.23828125" iyz="0.0" izz="0.16276041666666666"/>
    </inertial>
  </link>
  <link name="act_2_rod">
    <visual>
      <geometry>
        <cylinder length="0.35" radius="0.1"/>
      </geometry>
      <origin rpy="0 0 0" xyz="0 0 0.175"/>
    </visual>
    <collision>
      <geometry>
        <cylinder length="0.27999999999999997" radius="0.1"/>
      </geometry>
      <origin rpy="0 0 0" xyz="0 0 0.175"/>
    </collision>
    <inertial>
      <mass value="100"/>
      <inertia ixx="7.140624999999999" ixy="0.0" ixz="0.0" iyy="7.140624999999999" iyz="0.0" izz="0.13020833333333331"/>
    </inertial>
  </link>
  <joint name="jointb" type="revolute">
    <origin rpy="0 0 0" xyz="0 0 0"/>
    <parent link="base_link"/>
    <child link="arm_1"/>
    <axis xyz="0 0 1"/>
    <limit effort="30" lower="-3.141592653589793" upper="3.141592653589793" velocity="0.2"/>
  </joint>
  <joint name="joint1" type="revolute">
    <origin rpy="0 0 0" xyz="0 0 2.3000000000000003"/>
    <parent link="arm_1"/>
    <child link="arm_2"/>
    <axis xyz="1 0 0"/>
    <limit effort="30" lower="-0.2617993877991494" upper="1.0471975511965976" velocity="0.2"/>
  </joint>
  <joint name="joint2" type="revolute">
    <origin rpy="0 0 0" xyz="0 2.3 0"/>
    <parent link="arm_2"/>
    <child link="arm_3"/>
    <axis xyz="1 0 0"/>
    <limit effort="30" lower="-1.832595714594046" upper="-0.2617993877991494" velocity="0.2"/>
  </joint>
  <joint name="arm_3e" type="prismatic">
    <origin rpy="0 0 0" xyz="0 2.2 0"/>
    <parent link="arm_3"/>
    <child link="end_effector_temp"/>
    <axis xyz="0 1 0"/>
    <limit effort="30" lower="0" upper="2.0" velocity="0.25"/>
  </joint>
  <joint name="jointA1" type="continuous">
    <!-- Rot angle (x) = atan2(l_0-l_b1x, a_1-l_b1x)  -->
    <origin rpy="-0.1056 0 0" xyz="0 0.3 0.2"/>
    <parent link="arm_1"/>
    <child link="act_1_cyl"/>
    <axis xyz="1 0 0"/>
  </joint>
  <joint name="jointA1e" type="prismatic">
    <origin rpy="0 0 0" xyz="0 0 1.0"/>
    <parent link="act_1_cyl"/>
    <child link="act_1_rod"/>
    <axis xyz="0 0 1"/>
    <limit effort="30" lower="0" upper="0.75" velocity="0.2"/>
    <!-- <mimic joint="joint1" multiplier="${1.25}"/> -->
  </joint>
  <joint name="jointA2" type="continuous">
    <origin rpy="-1.7016960206944713 0 0" xyz="0 1.1 -0.275"/>
    <parent link="arm_2"/>
    <child link="act_2_cyl"/>
    <axis xyz="1 0 0"/>
  </joint>
  <joint name="jointA2e" type="prismatic">
    <origin rpy="0 0 0" xyz="0 0 0.6"/>
    <parent link="act_2_cyl"/>
    <child link="act_2_rod"/>
    <axis xyz="0 0 1"/>
    <limit effort="30" lower="0" upper="0.75" velocity="0.2"/>
    <!-- <mimic joint="joint2" multiplier="${1.25}"/> -->
  </joint>
</robot>
